Performing system checks...

Traceback (most recent call last):
  File "/Users/hmh/Project/chenbao_easy/chenbao_service/manage.py", line 22, in <module>
    execute_from_command_line(sys.argv)
  File "/Users/hmh/Project/chenbao_easy/chenbao_service/venv/lib/python2.7/site-packages/django/core/management/__init__.py", line 364, in execute_from_command_line
    utility.execute()
  File "/Users/hmh/Project/chenbao_easy/chenbao_service/venv/lib/python2.7/site-packages/django/core/management/__init__.py", line 356, in execute
    self.fetch_command(subcommand).run_from_argv(self.argv)
  File "/Users/hmh/Project/chenbao_easy/chenbao_service/venv/lib/python2.7/site-packages/django/core/management/base.py", line 283, in run_from_argv
    self.execute(*args, **cmd_options)
  File "/Users/hmh/Project/chenbao_easy/chenbao_service/venv/lib/python2.7/site-packages/django/core/management/commands/runserver.py", line 61, in execute
    super(Command, self).execute(*args, **options)
  File "/Users/hmh/Project/chenbao_easy/chenbao_service/venv/lib/python2.7/site-packages/django/core/management/base.py", line 330, in execute
    output = self.handle(*args, **options)
  File "/Users/hmh/Project/chenbao_easy/chenbao_service/venv/lib/python2.7/site-packages/django/core/management/commands/runserver.py", line 100, in handle
    self.run(**options)
  File "/Users/hmh/Project/chenbao_easy/chenbao_service/venv/lib/python2.7/site-packages/django/core/management/commands/runserver.py", line 111, in run
    self.inner_run(None, **options)
  File "/Users/hmh/Project/chenbao_easy/chenbao_service/venv/lib/python2.7/site-packages/django/core/management/commands/runserver.py", line 124, in inner_run
    self.check(display_num_errors=True)
  File "/Users/hmh/Project/chenbao_easy/chenbao_service/venv/lib/python2.7/site-packages/django/core/management/base.py", line 359, in check
    include_deployment_checks=include_deployment_checks,
  File "/Users/hmh/Project/chenbao_easy/chenbao_service/venv/lib/python2.7/site-packages/django/core/management/base.py", line 346, in _run_checks
    return checks.run_checks(**kwargs)
  File "/Users/hmh/Project/chenbao_easy/chenbao_service/venv/lib/python2.7/site-packages/django/core/checks/registry.py", line 81, in run_checks
    new_errors = check(app_configs=app_configs)
  File "/Users/hmh/Project/chenbao_easy/chenbao_service/venv/lib/python2.7/site-packages/django/core/checks/urls.py", line 16, in check_url_config
    return check_resolver(resolver)
  File "/Users/hmh/Project/chenbao_easy/chenbao_service/venv/lib/python2.7/site-packages/django/core/checks/urls.py", line 26, in check_resolver
    return check_method()
  File "/Users/hmh/Project/chenbao_easy/chenbao_service/venv/lib/python2.7/site-packages/django/urls/resolvers.py", line 256, in check
    for pattern in self.url_patterns:
  File "/Users/hmh/Project/chenbao_easy/chenbao_service/venv/lib/python2.7/site-packages/django/utils/functional.py", line 35, in __get__
    res = instance.__dict__[self.name] = self.func(instance)
  File "/Users/hmh/Project/chenbao_easy/chenbao_service/venv/lib/python2.7/site-packages/django/urls/resolvers.py", line 407, in url_patterns
    patterns = getattr(self.urlconf_module, "urlpatterns", self.urlconf_module)
  File "/Users/hmh/Project/chenbao_easy/chenbao_service/venv/lib/python2.7/site-packages/django/utils/functional.py", line 35, in __get__
    res = instance.__dict__[self.name] = self.func(instance)
  File "/Users/hmh/Project/chenbao_easy/chenbao_service/venv/lib/python2.7/site-packages/django/urls/resolvers.py", line 400, in urlconf_module
    return import_module(self.urlconf_name)
  File "/System/Library/Frameworks/Python.framework/Versions/2.7/lib/python2.7/importlib/__init__.py", line 37, in import_module
    __import__(name)
  File "/Users/hmh/Project/chenbao_easy/chenbao_service/chenbao_service/urls.py", line 30, in <module>
    url(r'^', views.run),
AttributeError: 'module' object has no attribute 'run'
